Workbook

Sheet Summary
A1: MyFinance Accounting Portal — Cost Summary
A2: AI-assisted build (Claude Code) · figures in EUR · v1 · 31 May 2026
A4: Development (one-time)
A5: PoC — de-risk extraction & reconciliation | C5: =Development!F44 -> 1320
A6: MVP — full multi-tenant product (labour) | C6: =Development!F45 -> 6480
A7: Claude Code subscription (PoC+MVP build) | C7: =Development!F48 -> 135.10393
A8: TOTAL development (PoC + MVP) | C8: =Development!F49 -> 7935.1039
A9: Future phase (optional, rough) | C9: =Development!F54 -> 8464.1109
A11: Running (recurring)
A12: Expected — per month | C12: ='Running Cost'!D13 -> 199
A13: Expected — per year | C13: ='Running Cost'!D13*12 -> 2388
A14: Range — per month (low / high) | C14: ='Running Cost'!C13 -> 93.5 | D14: ='Running Cost'!E13 -> 427
A16: Key assumptions
A17: • Oversight rate €40/h; 1× Claude Code Max ≈ €180/mo; ~30 oversight hrs/week.
A18: • Hours are HUMAN OVERSIGHT of Claude Code (code, tests, docs, user stories, IaC) — not full hand-coding.
A19: • Running cost at MVP scale (~1–3k companies); OCR/LLM are the main variables.
A20: • Stack: Java/Spring + worker on Hetzner, Supabase (DB+Auth+Storage), React PWA on Vercel/Cloudflare.
A21: • Excludes VAT, third-party setup fees, and human end-user support. Editable inputs are blue.

Sheet Assumptions
A1: MyFinance Accounting Portal — Estimation Assumptions & Methodology
A3: Development cost drivers
A4: Oversight / review rate (€ per hour) | B4: 40 | C4: Your time guiding & reviewing Claude Code (blue = editable input)
A5: Claude Code Max subscription (€ per month) | B5: 90 | C5: 1 seat, Max 5x tier
A6: Oversight hours per week | B6: 30 | C6: Productive human hours/week during the build
A7: Weeks per month | B7: 4.33 | C7: Constant
A9: Running cost drivers (OCR)
A10: Active client companies (MVP) | B10: 1500 | C10: Mid of ~1–3k target
A11: Paid-OCR pages per company per month | B11: 6 | C11: Most uploads are text PDFs parsed free in-process; only photo/scanned receipts hit paid OCR
A12: OCR price per 1,000 pages (€) | B12: 7 | C12: Managed Document-AI, pay-per-use
A13: OCR monthly (expected, €) | B13: =B10*B11*B12/1000 -> 63
A16: Methodology
A17: • Development is performed by Claude Code, which writes the code, tests, documentation, user stories,
A18: and infrastructure-as-code (Terraform). The hours below are HUMAN OVERSIGHT hours (guiding, reviewing,
A19: correcting, integrating) — not full hand-coding effort. A traditional human-team build of this scope would
A20: be several times higher in effort and cost.
A21: • Development cost = oversight hours × rate + Claude Code subscription over the build duration.
A22: • Build duration is derived from total hours ÷ (oversight hours/week × weeks/month).
A23: • Running cost is a separate monthly estimate at MVP scale, shown low / expected / high.
A24: • OCR and LLM usage are the main variable running costs; receipts-only OCR keeps it bounded, and a future
A25: e-Factura/ANAF integration would remove most invoice processing entirely.
A26: • Figures exclude VAT, one-off third-party setup (e.g. WhatsApp onboarding), and human end-user support.
A27: • Hosting per architecture v1: Java/Spring + worker on Hetzner (always-on), Supabase (DB+Auth+Storage),
A28: React PWA on Vercel/Cloudflare, managed Document-AI for receipts.

Sheet Development
A1: Development Estimation (AI-assisted build by Claude Code)
A3: ID | B3: Module / Workstream | C3: Phase | D3: Complexity | E3: Oversight hrs | F3: Labour cost
B4: — PoC: de-risk extraction + reconciliation —
A5: PoC-A | B5: Scaffolding + minimal auth/company setup | C5: PoC | D5: Medium | E5: 6 | F5: =E5*Assumptions!$B$4 -> 240
A6: PoC-B | B6: Extraction spike (VALIDATED on real BRD/BT/balance/D212 — build parser library) | C6: PoC | D6: High | E6: 12 | F6: =E6*Assumptions!$B$4 -> 480
A7: PoC-C | B7: Reconciliation engine + missing-document detection (logic proven) | C7: PoC | D7: Med-High | E7: 10 | F7: =E7*Assumptions!$B$4 -> 400
A8: PoC-D | B8: State-payment email auto-fill (amounts + deadline + treasury) | C8: PoC | D8: Medium | E8: 5 | F8: =E8*Assumptions!$B$4 -> 200
B9: PoC subtotal | E9: =SUM(E5:E8) -> 33 | F9: =SUM(F5:F8) -> 1320
B10: — MVP: full multi-tenant product —
A11: MOD-01 | B11: Tenant Administration | C11: MVP | D11: Medium | E11: 6 | F11: =E11*Assumptions!$B$4 -> 240
A12: MOD-02 | B12: Users, Accounts & Access (Supabase Auth, RBAC, RLS) | C12: MVP | D12: Med-High | E12: 8 | F12: =E12*Assumptions!$B$4 -> 320
A13: MOD-03 | B13: Client Company Management (tax profile, treasury, HR registry) | C13: MVP | D13: High | E13: 8 | F13: =E13*Assumptions!$B$4 -> 320
A14: MOD-04 | B14: Document Intake & Reconciliation (core differentiator; logic proven) | C14: MVP | D14: High | E14: 14 | F14: =E14*Assumptions!$B$4 -> 560
A15: MOD-05 | B15: Document Extraction Engine (per-bank parsers + per-decl XML mappers) | C15: MVP | D15: High | E15: 13 | F15: =E15*Assumptions!$B$4 -> 520
A16: MOD-06 | B16: Financial Statements & Reports | C16: MVP | D16: Med-High | E16: 8 | F16: =E16*Assumptions!$B$4 -> 320
A17: MOD-07 | B17: Fiscal Declarations & State Payments | C17: MVP | D17: Med-High | E17: 7 | F17: =E17*Assumptions!$B$4 -> 280
A18: MOD-08 | B18: Payroll (State de plata) | C18: MVP | D18: Low-Med | E18: 5 | F18: =E18*Assumptions!$B$4 -> 200
A19: MOD-09 | B19: Notifications Engine (email + in-app) | C19: MVP | D19: Med-High | E19: 8 | F19: =E19*Assumptions!$B$4 -> 320
A20: MOD-10 | B20: Internal Tasks | C20: MVP | D20: Low | E20: 4 | F20: =E20*Assumptions!$B$4 -> 160
A21: MOD-11 | B21: Dashboards (overview + tiles + new-companies; prototype-defined) | C21: MVP | D21: Medium | E21: 8 | F21: =E21*Assumptions!$B$4 -> 320
A22: MOD-12 | B22: Audit, Security & GDPR | C22: MVP | D22: Medium | E22: 8 | F22: =E22*Assumptions!$B$4 -> 320
... A29: X-05 | B29: Documentation + user-story backlog (Claude-generated, you review) | C29: MVP | D29: Low | E29: 3 | F29: =E29*Assumptions!$B$4 -> 120
B30: MVP subtotal | E30: =SUM(E11:E29) -> 162 | F30: =SUM(F11:F29) -> 6480
B31: — Future (rough, optional) —
A32: F-01 | B32: WhatsApp notification channel | C32: Future | D32: Low-Med | E32: 12 | F32: =E32*Assumptions!$B$4 -> 480
A33: F-02 | B33: e-Factura / ANAF SPV integration | C33: Future | D33: High | E33: 30 | F33: =E33*Assumptions!$B$4 -> 1200
A34: F-03 | B34: In-app two-way messaging | C34: Future | D34: Medium | E34: 24 | F34: =E34*Assumptions!$B$4 -> 960
A35: F-04 | B35: Native mobile app | C35: Future | D35: Very High | E35: 60 | F35: =E35*Assumptions!$B$4 -> 2400
A36: F-05 | B36: Per-employee payslip distribution | C36: Future | D36: Low-Med | E36: 12 | F36: =E36*Assumptions!$B$4 -> 480
A37: F-06 | B37: Payroll-system integration | C37: Future | D37: Medium | E37: 20 | F37: =E37*Assumptions!$B$4 -> 800
A38: F-07 | B38: Per-tenant template customization | C38: Future | D38: Medium | E38: 16 | F38: =E38*Assumptions!$B$4 -> 640
A39: F-08 | B39: Per-employee company-access restriction | C39: Future | D39: Low | E39: 10 | F39: =E39*Assumptions!$B$4 -> 400
A40: F-09 | B40: Database-per-tenant premium tier | C40: Future | D40: Med-High | E40: 24 | F40: =E40*Assumptions!$B$4 -> 960
B41: Future subtotal | E41: =SUM(E32:E40) -> 208 | F41: =SUM(F32:F40) -> 8320
B43: Cost summary
B44: PoC — labour (oversight) | F44: =F9 -> 1320
B45: MVP — labour (oversight) | F45: =F30 -> 6480
B46: PoC+MVP — total oversight hours | F46: =E9+E30 -> 195
B47: PoC+MVP — build duration (months) | F47: =(E9+E30)/(Assumptions!$B$6*Assumptions!$B$7) -> 1.5011547
B48: PoC+MVP — Claude Code subscription | F48: =F47*Assumptions!$B$5 -> 135.10393
...

Sheet Running Cost
A1: Running Cost — Monthly (MVP scale)
A3: Item | B3: Notes | C3: Low (€/mo) | D3: Expected (€/mo) | E3: High (€/mo)
A4: Hetzner — backend app server | B4: Spring API (CPX31-class) | C4: 9 | D4: 15 | E4: 30
A5: Hetzner — worker server | B5: Extraction/notification worker (CPX21-class) | C5: 5 | D5: 8 | E5: 16
A6: Redis / queue | B6: Small instance or Postgres pgmq | C6: 0 | D6: 5 | E6: 10
A7: Supabase Pro | B7: Postgres + Auth + Storage (+ storage overage) | C7: 23 | D7: 28 | E7: 45
A8: Frontend hosting | B8: Vercel/Cloudflare (free → Pro) | C8: 0 | D8: 0 | E8: 20
A9: Document-AI OCR | B9: Receipts only, pay-per-use (=Assumptions OCR) | C9: =D9*0.5 -> 31.5 | D9: =Assumptions!$B$13 -> 63 | E9: =D9*2 -> 126
A10: LLM (chatbot) | B10: Usage-based, modest at MVP | C10: 20 | D10: 50 | E10: 120
A11: Transactional email | B11: Report/tax/payroll/notification email | C11: 0 | D11: 20 | E11: 40
A12: Domain, TLS, misc | B12: DNS, certs, monitoring buffer | C12: 5 | D12: 10 | E12: 20
A13: Total per month | C13: =SUM(C4:C12) -> 93.5 | D13: =SUM(D4:D12) -> 199 | E13: =SUM(E4:E12) -> 427
A14: Total per year | C14: =C13*12 -> 1122 | D14: =D13*12 -> 2388 | E14: =E13*12 -> 5124
A16: OCR and LLM are the main variable costs; receipts-only OCR bounds them, and a future e-Factura integration removes most invoice processing.
